{"trial_id": "2", "hyperparameters": {"space": [{"class_name": "Int", "config": {"name": "units", "default": null, "conditions": [], "min_value": 32, "max_value": 512, "step": 32, "sampling": "linear"}}], "values": {"units": 32}}, "metrics": {"metrics": {"accuracy": {"direction": "max", "observations": [{"value": [0.6557676196098328], "step": 9}]}, "loss": {"direction": "min", "observations": [{"value": [0.7356743216514587], "step": 9}]}, "val_accuracy": {"direction": "max", "observations": [{"value": [0.6603535413742065], "step": 9}]}, "val_loss": {"direction": "min", "observations": [{"value": [0.7271387577056885], "step": 9}]}}}, "score": 0.6603535413742065, "best_step": 9, "status": "COMPLETED", "message": "Traceback (most recent call last):\n  File \"C:\\Users\\User\\anaconda3\\lib\\site-packages\\keras_tuner\\src\\engine\\base_tuner.py\", line 273, in _try_run_and_update_trial\n    self._run_and_update_trial(trial, *fit_args, **fit_kwargs)\n  File \"C:\\Users\\User\\anaconda3\\lib\\site-packages\\keras_tuner\\src\\engine\\base_tuner.py\", line 238, in _run_and_update_trial\n    results = self.run_trial(trial, *fit_args, **fit_kwargs)\n  File \"C:\\Users\\User\\anaconda3\\lib\\site-packages\\keras_tuner\\src\\engine\\tuner.py\", line 314, in run_trial\n    obj_value = self._build_and_fit_model(trial, *args, **copied_kwargs)\n  File \"C:\\Users\\User\\anaconda3\\lib\\site-packages\\keras_tuner\\src\\engine\\tuner.py\", line 233, in _build_and_fit_model\n    results = self.hypermodel.fit(hp, model, *args, **kwargs)\n  File \"C:\\Users\\User\\anaconda3\\lib\\site-packages\\keras_tuner\\src\\engine\\hypermodel.py\", line 149, in fit\n    return model.fit(*args, **kwargs)\n  File \"C:\\Users\\User\\anaconda3\\lib\\site-packages\\keras\\src\\utils\\traceback_utils.py\", line 123, in error_handler\n    # Get original error message and append information to it.\n  File \"C:\\Users\\User\\AppData\\Roaming\\Python\\Python39\\site-packages\\tensorflow\\python\\eager\\execute.py\", line 53, in quick_execute\n    tensors = pywrap_tfe.TFE_Py_Execute(ctx._handle, device_name, op_name,\ntensorflow.python.framework.errors_impl.InvalidArgumentError: Graph execution error:\n\nDetected at node compile_loss/sparse_categorical_crossentropy/SparseSoftmaxCrossEntropyWithLogits/SparseSoftmaxCrossEntropyWithLogits defined at (most recent call last):\n  File \"C:\\Users\\User\\anaconda3\\lib\\runpy.py\", line 197, in _run_module_as_main\n\n  File \"C:\\Users\\User\\anaconda3\\lib\\runpy.py\", line 87, in _run_code\n\n  File \"C:\\Users\\User\\AppData\\Roaming\\Python\\Python39\\site-packages\\ipykernel_launcher.py\", line 17, in <module>\n\n  File \"C:\\Users\\User\\anaconda3\\lib\\site-packages\\traitlets\\config\\application.py\", line 1043, in launch_instance\n\n  File \"C:\\Users\\User\\AppData\\Roaming\\Python\\Python39\\site-packages\\ipykernel\\kernelapp.py\", line 725, in start\n\n  File \"C:\\Users\\User\\anaconda3\\lib\\site-packages\\tornado\\platform\\asyncio.py\", line 195, in start\n\n  File \"C:\\Users\\User\\anaconda3\\lib\\asyncio\\base_events.py\", line 601, in run_forever\n\n  File \"C:\\Users\\User\\anaconda3\\lib\\asyncio\\base_events.py\", line 1905, in _run_once\n\n  File \"C:\\Users\\User\\anaconda3\\lib\\asyncio\\events.py\", line 80, in _run\n\n  File \"C:\\Users\\User\\AppData\\Roaming\\Python\\Python39\\site-packages\\ipykernel\\kernelbase.py\", line 513, in dispatch_queue\n\n  File \"C:\\Users\\User\\AppData\\Roaming\\Python\\Python39\\site-packages\\ipykernel\\kernelbase.py\", line 502, in process_one\n\n  File \"C:\\Users\\User\\AppData\\Roaming\\Python\\Python39\\site-packages\\ipykernel\\kernelbase.py\", line 409, in dispatch_shell\n\n  File \"C:\\Users\\User\\AppData\\Roaming\\Python\\Python39\\site-packages\\ipykernel\\kernelbase.py\", line 729, in execute_request\n\n  File \"C:\\Users\\User\\AppData\\Roaming\\Python\\Python39\\site-packages\\ipykernel\\ipkernel.py\", line 422, in do_execute\n\n  File \"C:\\Users\\User\\AppData\\Roaming\\Python\\Python39\\site-packages\\ipykernel\\zmqshell.py\", line 540, in run_cell\n\n  File \"C:\\Users\\User\\AppData\\Roaming\\Python\\Python39\\site-packages\\IPython\\core\\interactiveshell.py\", line 2975, in run_cell\n\n  File \"C:\\Users\\User\\AppData\\Roaming\\Python\\Python39\\site-packages\\IPython\\core\\interactiveshell.py\", line 3030, in _run_cell\n\n  File \"C:\\Users\\User\\AppData\\Roaming\\Python\\Python39\\site-packages\\IPython\\core\\async_helpers.py\", line 78, in _pseudo_sync_runner\n\n  File \"C:\\Users\\User\\AppData\\Roaming\\Python\\Python39\\site-packages\\IPython\\core\\interactiveshell.py\", line 3257, in run_cell_async\n\n  File \"C:\\Users\\User\\AppData\\Roaming\\Python\\Python39\\site-packages\\IPython\\core\\interactiveshell.py\", line 3473, in run_ast_nodes\n\n  File \"C:\\Users\\User\\AppData\\Roaming\\Python\\Python39\\site-packages\\IPython\\core\\interactiveshell.py\", line 3553, in run_code\n\n  File \"C:\\Users\\User\\AppData\\Local\\Temp\\ipykernel_5408\\1019289132.py\", line 1, in <cell line: 1>\n\n  File \"C:\\Users\\User\\anaconda3\\lib\\site-packages\\keras_tuner\\src\\engine\\base_tuner.py\", line 233, in search\n\n  File \"C:\\Users\\User\\anaconda3\\lib\\site-packages\\keras_tuner\\src\\engine\\base_tuner.py\", line 273, in _try_run_and_update_trial\n\n  File \"C:\\Users\\User\\anaconda3\\lib\\site-packages\\keras_tuner\\src\\engine\\base_tuner.py\", line 238, in _run_and_update_trial\n\n  File \"C:\\Users\\User\\anaconda3\\lib\\site-packages\\keras_tuner\\src\\engine\\tuner.py\", line 314, in run_trial\n\n  File \"C:\\Users\\User\\anaconda3\\lib\\site-packages\\keras_tuner\\src\\engine\\tuner.py\", line 233, in _build_and_fit_model\n\n  File \"C:\\Users\\User\\anaconda3\\lib\\site-packages\\keras_tuner\\src\\engine\\hypermodel.py\", line 149, in fit\n\n  File \"C:\\Users\\User\\anaconda3\\lib\\site-packages\\keras\\src\\utils\\traceback_utils.py\", line 118, in error_handler\n\n  File \"C:\\Users\\User\\anaconda3\\lib\\site-packages\\keras\\src\\backend\\tensorflow\\trainer.py\", line 323, in fit\n\n  File \"C:\\Users\\User\\anaconda3\\lib\\site-packages\\keras\\src\\backend\\tensorflow\\trainer.py\", line 117, in one_step_on_iterator\n\n  File \"C:\\Users\\User\\anaconda3\\lib\\site-packages\\keras\\src\\backend\\tensorflow\\trainer.py\", line 105, in one_step_on_data\n\n  File \"C:\\Users\\User\\anaconda3\\lib\\site-packages\\keras\\src\\backend\\tensorflow\\trainer.py\", line 59, in train_step\n\n  File \"C:\\Users\\User\\anaconda3\\lib\\site-packages\\keras\\src\\trainers\\trainer.py\", line 321, in compute_loss\n\n  File \"C:\\Users\\User\\anaconda3\\lib\\site-packages\\keras\\src\\trainers\\compile_utils.py\", line 606, in __call__\n\n  File \"C:\\Users\\User\\anaconda3\\lib\\site-packages\\keras\\src\\trainers\\compile_utils.py\", line 642, in call\n\n  File \"C:\\Users\\User\\anaconda3\\lib\\site-packages\\keras\\src\\losses\\loss.py\", line 43, in __call__\n\n  File \"C:\\Users\\User\\anaconda3\\lib\\site-packages\\keras\\src\\losses\\losses.py\", line 22, in call\n\n  File \"C:\\Users\\User\\anaconda3\\lib\\site-packages\\keras\\src\\losses\\losses.py\", line 1714, in sparse_categorical_crossentropy\n\n  File \"C:\\Users\\User\\anaconda3\\lib\\site-packages\\keras\\src\\ops\\nn.py\", line 1541, in sparse_categorical_crossentropy\n\n  File \"C:\\Users\\User\\anaconda3\\lib\\site-packages\\keras\\src\\backend\\tensorflow\\nn.py\", line 633, in sparse_categorical_crossentropy\n\nReceived a label value of 3 which is outside the valid range of [0, 3).  Label values: 2 2 1 2 2 2 2 2 1 3 1 3 2 1 2 2 1 2 3 2 3 2 3 1 2 2 1 3 2 3 3 3\n\t [[{{node compile_loss/sparse_categorical_crossentropy/SparseSoftmaxCrossEntropyWithLogits/SparseSoftmaxCrossEntropyWithLogits}}]] [Op:__inference_one_step_on_iterator_212549]\n"}